[33mWARNING [0m urllib3.connectionpool:connectionpool.py:871 Retrying (Retry(total=2, connect=None, read=None, redirect=None, status=None)) after connection broken by 'ConnectTimeoutError(<urllib3.connection.HTTPConnection object at 0x0000020863C32710>, 'Connection to 172.17.0.2 timed out. (connect timeout=None)')': /wd/hub/session
[33mWARNING [0m urllib3.connectionpool:connectionpool.py:871 Retrying (Retry(total=1, connect=None, read=None, redirect=None, status=None)) after connection broken by 'ConnectTimeoutError(<urllib3.connection.HTTPConnection object at 0x0000020863C4D1D0>, 'Connection to 172.17.0.2 timed out. (connect timeout=None)')': /wd/hub/session
[33mWARNING [0m urllib3.connectionpool:connectionpool.py:871 Retrying (Retry(total=0, connect=None, read=None, redirect=None, status=None)) after connection broken by 'ConnectTimeoutError(<urllib3.connection.HTTPConnection object at 0x0000020863C4DD10>, 'Connection to 172.17.0.2 timed out. (connect timeout=None)')': /wd/hub/session