{"uuid": "aac1188c-2f38-4b94-be14-1a870433b058", "children": ["d618e820-2568-4529-939b-3c5edd30a8a9"], "befores": [{"name": "browser", "status": "broken", "statusDetails": {"message": "selenium.common.exceptions.WebDriverException: Message: Service /root/.cache/selenium/chromedriver/linux64/118.0.5993.70/chromedriver unexpectedly exited. Status code was: 127\n\n", "trace": "  File \"/usr/local/lib/python3.11/site-packages/pluggy/_callers.py\", line 80, in _multicall\n    res = hook_impl.function(*args)\n          ^^^^^^^^^^^^^^^^^^^^^^^^^\n  File \"/usr/local/lib/python3.11/site-packages/_pytest/fixtures.py\", line 1123, in pytest_fixture_setup\n    result = call_fixture_func(fixturefunc, request, kwargs)\n             ^^^^^^^^^^^^^^^^^^^^^^^^^^^^^^^^^^^^^^^^^^^^^^^\n  File \"/usr/local/lib/python3.11/site-packages/_pytest/fixtures.py\", line 895, in call_fixture_func\n    fixture_result = next(generator)\n                     ^^^^^^^^^^^^^^^\n  File \"/photobank_autotests/conftest.py\", line 10, in browser\n    browser = webdriver.Chrome()\n              ^^^^^^^^^^^^^^^^^^\n  File \"/usr/local/lib/python3.11/site-packages/selenium/webdriver/chrome/webdriver.py\", line 45, in __init__\n    super().__init__(\n  File \"/usr/local/lib/python3.11/site-packages/selenium/webdriver/chromium/webdriver.py\", line 53, in __init__\n    self.service.start()\n  File \"/usr/local/lib/python3.11/site-packages/selenium/webdriver/common/service.py\", line 102, in start\n    self.assert_process_still_running()\n  File \"/usr/local/lib/python3.11/site-packages/selenium/webdriver/common/service.py\", line 115, in assert_process_still_running\n    raise WebDriverException(f\"Service {self._path} unexpectedly exited. Status code was: {return_code}\")\n"}, "start": 1698068164441, "stop": 1698068164949}], "start": 1698068164441, "stop": 1698068164960}